<?xml version='1.0' encoding='utf-8'?>
<robot name="FPGA_bot">
    <link name="AX-12A-02">
        <inertial>
            <origin xyz="0.0004775574469091648 -5.827164262228735e-09 0.02385609451097132" rpy="0.0 -0.0 0.0" />
            <mass value="0.32390152119562815" />
            <inertia ixx="7.890001762359596e-05" iyy="9.10337982403032e-05" izz="4.960220935442284e-05" ixy="2.0839870194105936e-11" iyz="6.897859844076648e-11" ixz="1.6464754014779539e-06" />
        </inertial>
        <visual name="AX-12A-02_visual">
            <origin xyz="0.013500000000000033 0.0 0.03699999944865695" rpy="5.7475132325822575e-46 1.5707963267948954 0" />
            <geometry>
                <mesh filename="package://moveit_bot_fpga_bot_description/meshes/AX-12A-02.stl" scale="0.001 0.001 0.001" />
            </geometry>
        </visual>
        <collision name="AX-12A-02_collision">
            <origin xyz="0.013500000000000033 0.0 0.03699999944865695" rpy="5.7475132325822575e-46 1.5707963267948954 0" />
            <geometry>
                <mesh filename="package://moveit_bot_fpga_bot_description/meshes/AX-12A-02.stl" scale="0.001 0.001 0.001" />
            </geometry>
        </collision>
    </link>
    <link name="AX-12A-04">
        <inertial>
            <origin xyz="5.512533540752429e-10 -1.7763568394002505e-17 0.0020767750500773107" rpy="0.0 -0.0 0.0" />
            <mass value="0.013145620261527293" />
            <inertia ixx="4.2556522474073355e-07" iyy="4.255652253532671e-07" izz="7.952268273435782e-07" ixy="-1.3552527156068805e-20" iyz="2.710505431213761e-20" ixz="-2.236166980751353e-18" />
        </inertial>
        <visual name="AX-12A-04_visual">
            <origin xyz="5.513430423320642e-10 0.0 0.004500000000000028" rpy="-5.071403158464064e-22 -1.985233470127261e-22 -5.138677268548816e-53" />
            <geometry>
                <mesh filename="package://moveit_bot_fpga_bot_description/meshes/AX-12A-04.stl" scale="0.001 0.001 0.001" />
            </geometry>
        </visual>
        <collision name="AX-12A-04_collision">
            <origin xyz="5.513430423320642e-10 0.0 0.004500000000000028" rpy="-5.071403158464064e-22 -1.985233470127261e-22 -5.138677268548816e-53" />
            <geometry>
                <mesh filename="package://moveit_bot_fpga_bot_description/meshes/AX-12A-04.stl" scale="0.001 0.001 0.001" />
            </geometry>
        </collision>
    </link>
    <link name="plate">
        <inertial>
            <origin xyz="-0.06011025200913953 -0.062292971575455484 -0.0385" rpy="0.0 0.0 0.0" />
            <mass value="0.5548736897893473" />
            <inertia ixx="0.003500086381477631" iyy="0.003077615843439447" izz="0.006576869914382395" ixy="3.810831036574855e-06" iyz="3.3203691532368573e-19" ixz="-4.3145740750765924e-20" />
        </inertial>
        <visual name="plate_visual">
            <origin xyz="0.0 0.0 0.0" rpy="0.0 0.0 0.0" />
            <geometry>
                <mesh filename="package://moveit_bot_fpga_bot_description/meshes/plate.stl" scale="0.001 0.001 0.001" />
            </geometry>
        </visual>
        <collision name="plate_collision">
            <origin xyz="0.0 0.0 0.0" rpy="0.0 0.0 0.0" />
            <geometry>
                <mesh filename="package://moveit_bot_fpga_bot_description/meshes/plate.stl" scale="0.001 0.001 0.001" />
            </geometry>
        </collision>
    </link>
    <link name="Motor_holder_plate">
        <inertial>
            <origin xyz="-0.0010491940230658336 0.006000000000000014 0.02043335893321079" rpy="0.0 -0.0 0.0" />
            <mass value="0.1791312239025152" />
            <inertia ixx="8.533702654904031e-05" iyy="6.337964634902825e-05" izz="6.800406458345749e-05" ixy="2.168404344971009e-19" iyz="-5.421010862427522e-20" ixz="-5.3519017307861335e-06" />
        </inertial>
        <visual name="Motor_holder_plate_visual">
            <origin xyz="-0.022499999999999947 0.005999999999999997 0.037000000000000026" rpy="-6.162975822039066e-33 1.1657341758564144e-15 0.0" />
            <geometry>
                <mesh filename="package://moveit_bot_fpga_bot_description/meshes/Motor_holder_plate.stl" scale="0.001 0.001 0.001" />
            </geometry>
        </visual>
        <collision name="Motor_holder_plate_collision">
            <origin xyz="-0.022499999999999947 0.005999999999999997 0.037000000000000026" rpy="-6.162975822039066e-33 1.1657341758564144e-15 0.0" />
            <geometry>
                <mesh filename="package://moveit_bot_fpga_bot_description/meshes/Motor_holder_plate.stl" scale="0.001 0.001 0.001" />
            </geometry>
        </collision>
    </link>
    <link name="2nd_motor_arm90deg">
        <inertial>
            <origin xyz="-0.040195252977123674 0.00010019366635527049 -0.020620760616514112" rpy="0.0 -0.0 0.0" />
            <mass value="0.2605961471797569" />
            <inertia ixx="6.273259040474573e-05" iyy="0.00019487221554548046" izz="0.00016749966326599962" ixy="2.3490097782337925e-07" iyz="8.917058413058024e-09" ixz="-5.848948483657448e-06" />
        </inertial>
        <visual name="2nd_motor_arm90deg_visual">
            <origin xyz="5.513432999038059e-10 -0.1000000000000002 -0.021000000000000078" rpy="1.8151019493291513e-18 -2.9102856759964347e-22 -1.5707963267948943" />
            <geometry>
                <mesh filename="package://moveit_bot_fpga_bot_description/meshes/2nd_motor_arm90deg.stl" scale="0.001 0.001 0.001" />
            </geometry>
        </visual>
        <collision name="2nd_motor_arm90deg_collision">
            <origin xyz="5.513432999038059e-10 -0.1000000000000002 -0.021000000000000078" rpy="1.8151019493291513e-18 -2.9102856759964347e-22 -1.5707963267948943" />
            <geometry>
                <mesh filename="package://moveit_bot_fpga_bot_description/meshes/2nd_motor_arm90deg.stl" scale="0.001 0.001 0.001" />
            </geometry>
        </collision>
    </link>
    <link name="AX-12A-041">
        <inertial>
            <origin xyz="1.1025960233723708e-09 -1.9539925233402755e-16 0.0020767735388075616" rpy="0.0 -0.0 0.0" />
            <mass value="0.013145620261527293" />
            <inertia ixx="4.2556522474076065e-07" iyy="4.255652253532671e-07" izz="7.952268273435782e-07" ixy="3.81432317681084e-39" iyz="2.710505431213761e-20" ixz="-2.23955511254037e-18" />
        </inertial>
        <visual name="AX-12A-041_visual">
            <origin xyz="1.1026857116291921e-09 -1.9539925233402755e-16 0.0044999984887302705" rpy="-1.487644743403084e-16 -1.9852334701272612e-22 2.7755575615629027e-16" />
            <geometry>
                <mesh filename="package://moveit_bot_fpga_bot_description/meshes/AX-12A-041.stl" scale="0.001 0.001 0.001" />
            </geometry>
        </visual>
        <collision name="AX-12A-041_collision">
            <origin xyz="1.1026857116291921e-09 -1.9539925233402755e-16 0.0044999984887302705" rpy="-1.487644743403084e-16 -1.9852334701272612e-22 2.7755575615629027e-16" />
            <geometry>
                <mesh filename="package://moveit_bot_fpga_bot_description/meshes/AX-12A-041.stl" scale="0.001 0.001 0.001" />
            </geometry>
        </collision>
    </link>
    <link name="AX-12A-021">
        <inertial>
            <origin xyz="-0.023856093959628687 0.0004775559356395576 5.827164404337282e-09" rpy="0.0 -0.0 0.0" />
            <mass value="0.32390152119562815" />
            <inertia ixx="4.960220935442371e-05" iyy="7.89000176235951e-05" izz="9.103379824030309e-05" ixy="-1.6464754014779539e-06" iyz="-2.083987041094637e-11" ixz="6.897859833234626e-11" />
        </inertial>
        <visual name="AX-12A-021_visual">
            <origin xyz="-0.036999998897314305 0.013499998488730328 1.4210854715202004e-16" rpy="-1.5707963267948968 2.775557561562899e-16 1.8151019493286186e-18" />
            <geometry>
                <mesh filename="package://moveit_bot_fpga_bot_description/meshes/AX-12A-021.stl" scale="0.001 0.001 0.001" />
            </geometry>
        </visual>
        <collision name="AX-12A-021_collision">
            <origin xyz="-0.036999998897314305 0.013499998488730328 1.4210854715202004e-16" rpy="-1.5707963267948968 2.775557561562899e-16 1.8151019493286186e-18" />
            <geometry>
                <mesh filename="package://moveit_bot_fpga_bot_description/meshes/AX-12A-021.stl" scale="0.001 0.001 0.001" />
            </geometry>
        </collision>
    </link>
    <link name="new_2nd_arm_bothsamedirection-v1">
        <inertial>
            <origin xyz="0.00017437366938449994 -0.02985835547607774 -0.01997933512757073" rpy="0.0 -0.0 0.0" />
            <mass value="0.19255111641644582" />
            <inertia ixx="0.00010538646765974194" iyy="5.766623194024961e-05" izz="6.205041311811927e-05" ixy="6.707539424499536e-07" iyz="-2.56198313386153e-06" ixz="1.7968134400389406e-08" />
        </inertial>
        <visual name="new_2nd_arm_bothsamedirection-v1_visual">
            <origin xyz="0.15138807387108918 -8.881784197001253e-17 -0.04830856887228711" rpy="-1.4876396719999184e-16 4.129022648788754e-32 2.775557561562902e-16" />
            <geometry>
                <mesh filename="package://moveit_bot_fpga_bot_description/meshes/new_2nd_arm_bothsamedirection-v1.stl" scale="0.001 0.001 0.001" />
            </geometry>
        </visual>
        <collision name="new_2nd_arm_bothsamedirection-v1_collision">
            <origin xyz="0.15138807387108918 -8.881784197001253e-17 -0.04830856887228711" rpy="-1.4876396719999184e-16 4.129022648788754e-32 2.775557561562902e-16" />
            <geometry>
                <mesh filename="package://moveit_bot_fpga_bot_description/meshes/new_2nd_arm_bothsamedirection-v1.stl" scale="0.001 0.001 0.001" />
            </geometry>
        </collision>
    </link>
    <link name="AX-12A-022">
        <inertial>
            <origin xyz="0.0004775526848829159 -8.301174077018914e-09 0.023856091109291686" rpy="0.0 -0.0 0.0" />
            <mass value="0.32390152119562815" />
            <inertia ixx="7.890001762359683e-05" iyy="9.103379824030255e-05" izz="4.960220935442414e-05" ixy="2.0839870194105936e-11" iyz="6.897859833234626e-11" ixz="1.6464754014779539e-06" />
        </inertial>
        <visual name="AX-12A-022_visual">
            <origin xyz="0.01349999523797377 -2.474009810349287e-09 0.03699999604697733" rpy="-0.0 1.5707963267948963 0" />
            <geometry>
                <mesh filename="package://moveit_bot_fpga_bot_description/meshes/AX-12A-022.stl" scale="0.001 0.001 0.001" />
            </geometry>
        </visual>
        <collision name="AX-12A-022_collision">
            <origin xyz="0.01349999523797377 -2.474009810349287e-09 0.03699999604697733" rpy="-0.0 1.5707963267948963 0" />
            <geometry>
                <mesh filename="package://moveit_bot_fpga_bot_description/meshes/AX-12A-022.stl" scale="0.001 0.001 0.001" />
            </geometry>
        </collision>
    </link>
    <link name="AX-12A-042">
        <inertial>
            <origin xyz="0.0020767702880510486 3.95302263811459e-09 -2.4739201220924656e-09" rpy="0.0 -0.0 0.0" />
            <mass value="0.013145620261527293" />
            <inertia ixx="7.952268273436663e-07" iyy="4.2556522535328744e-07" izz="4.255652247408013e-07" ixy="-1.9603854839823683e-38" iyz="-5.50236125017143e-50" ixz="2.2327788489623357e-18" />
        </inertial>
        <visual name="AX-12A-042_visual">
            <origin xyz="0.004499995237973771 3.953022646996374e-09 -2.474009810349287e-09" rpy="-2.7755575615629007e-16 1.5707963267948946 0" />
            <geometry>
                <mesh filename="package://moveit_bot_fpga_bot_description/meshes/AX-12A-042.stl" scale="0.001 0.001 0.001" />
            </geometry>
        </visual>
        <collision name="AX-12A-042_collision">
            <origin xyz="0.004499995237973771 3.953022646996374e-09 -2.474009810349287e-09" rpy="-2.7755575615629007e-16 1.5707963267948946 0" />
            <geometry>
                <mesh filename="package://moveit_bot_fpga_bot_description/meshes/AX-12A-042.stl" scale="0.001 0.001 0.001" />
            </geometry>
        </collision>
    </link>
    <link name="pencil_holder_v2">
        <inertial>
            <origin xyz="-0.01970496178457984 -0.021336590766325787 -0.0006275359579855478" rpy="0.0 -0.0 0.0" />
            <mass value="0.12670142746144467" />
            <inertia ixx="2.007973010216405e-05" iyy="4.346229586575266e-05" izz="5.454636599275034e-05" ixy="-1.6871998019554703e-06" iyz="-1.3697947469247713e-06" ixz="-6.059128008147909e-08" />
        </inertial>
        <visual name="pencil_holder_v2_visual">
            <origin xyz="-0.04830857212304362 3.953022340574819e-09 -0.15138807524241327" rpy="-2.7755575615629096e-16 1.5707963267948946 0" />
            <geometry>
                <mesh filename="package://moveit_bot_fpga_bot_description/meshes/pencil_holder_v2.stl" scale="0.001 0.001 0.001" />
            </geometry>
        </visual>
        <collision name="pencil_holder_v2_collision">
            <origin xyz="-0.04830857212304362 3.953022340574819e-09 -0.15138807524241327" rpy="-2.7755575615629096e-16 1.5707963267948946 0" />
            <geometry>
                <mesh filename="package://moveit_bot_fpga_bot_description/meshes/pencil_holder_v2.stl" scale="0.001 0.001 0.001" />
            </geometry>
        </collision>
    </link>
    <joint name="plate_Rigid-4" type="fixed">
        <origin xyz="0.0225 -0.005999999999999997 -0.037000000000000005" rpy="0.0 -0.0 0.0" />
        <parent link="plate" />
        <child link="Motor_holder_plate" />
    </joint>
    <joint name="Motor_holder_plate_Rigid-5" type="fixed">
        <origin xyz="0.014499999999999994 0.005999999999999997 0.037000000000000005" rpy="-0.0 -1.5707963267948966 0" />
        <parent link="Motor_holder_plate" />
        <child link="AX-12A-02" />
    </joint>
    <joint name="AX-12A-02_Revolute-6" type="continuous">
        <origin xyz="0.01625 0.0 0.03699999999999999" rpy="-0.0 1.5707963267948966 0" />
        <parent link="AX-12A-02" />
        <child link="AX-12A-04" />
        <axis xyz="0.0 0.0 1.0" />
    </joint>
    <joint name="AX-12A-04_Rigid-7" type="fixed">
        <origin xyz="0.0 0.0 0.004500000000000002" rpy="0.0 -2.350988701644575e-38 0.0" />
        <parent link="AX-12A-04" />
        <child link="2nd_motor_arm90deg" />
    </joint>
    <joint name="2nd_motor_arm90deg_Rigid-8" type="fixed">
        <origin xyz="-0.063 0.0 -0.021467020000000003" rpy="1.5707963267948966 2.350988701644575e-38 3.944304526104212e-31" />
        <parent link="2nd_motor_arm90deg" />
        <child link="AX-12A-021" />
    </joint>
    <joint name="AX-12A-021_Revolute-9" type="continuous">
        <origin xyz="-0.037000000000000005 0.01625 0.0" rpy="-1.5707963267948966 -4.440042809535891e-31 0.0" />
        <parent link="AX-12A-021" />
        <child link="AX-12A-041" />
        <axis xyz="0.0 0.0 1.0" />
    </joint>
    <joint name="AX-12A-041_Rigid-10" type="fixed">
        <origin xyz="0.0 0.0 0.004500000000000002" rpy="0.0 -0.0 4.957379881004711e-32" />
        <parent link="AX-12A-041" />
        <child link="new_2nd_arm_bothsamedirection-v1" />
    </joint>
    <joint name="new_2nd_arm_bothsamedirection-v1_Rigid-11" type="fixed">
        <origin xyz="0.0005898000000000004 -0.03725339 -0.020512429999999998" rpy="1.5707963267948966 -0.0 2.9533120689576276e-38" />
        <parent link="new_2nd_arm_bothsamedirection-v1" />
        <child link="AX-12A-022" />
    </joint>
    <joint name="AX-12A-022_Revolute-12" type="continuous">
        <origin xyz="0.01625 0.0 0.037000000000000005" rpy="-1.5707963267948966 -6.142497898924336e-48 -5.25369090118809e-47" />
        <parent link="AX-12A-022" />
        <child link="AX-12A-042" />
        <axis xyz="1.0 -2.465190328815662e-32 0.0" />
    </joint>
    <joint name="AX-12A-042_Rigid-13" type="fixed">
        <origin xyz="0.0045 0.0 0.0" rpy="-4.285127577202577e-38 -5.25369090118809e-47 0.0" />
        <parent link="AX-12A-042" />
        <child link="pencil_holder_v2" />
    </joint>
</robot>