<?xml version='1.0' encoding='utf-8'?>
<robot name="Rope_joint">
    <link name="Joint_M">
        <inertial>
            <origin xyz="-0.0002839247464924666 -0.006161159613505424 7.145082342513579e-06" rpy="0.0 0.0 0.0" />
            <mass value="0.9819872908083896" />
            <inertia ixx="0.0015691400990050248" iyy="0.0010440284532366188" izz="0.0005938467225559531" ixy="-2.54501738942687e-05" iyz="-2.5368626355909854e-07" ixz="-2.0433730024363433e-09" />
        </inertial>
        <visual name="Joint_M_visual">
            <origin xyz="0.0 0.0 0.0" rpy="0.0 0.0 0.0" />
            <geometry>
                <mesh filename="package://moveit_bot_rope_bot_description/meshes/Joint_M.stl" scale="0.001 0.001 0.001" />
            </geometry>
        </visual>
        <collision name="Joint_M_collision">
            <origin xyz="0.0 0.0 0.0" rpy="0.0 0.0 0.0" />
            <geometry>
                <mesh filename="package://moveit_bot_rope_bot_description/meshes/Joint_M.stl" scale="0.001 0.001 0.001" />
            </geometry>
        </collision>
    </link>
    <link name="Joint">
        <inertial>
            <origin xyz="7.16396169102725e-06 -0.006161140412826924 0.01028392488404295" rpy="0.0 -0.0 0.0" />
            <mass value="0.9819884881906905" />
            <inertia ixx="0.0005938487526789809" iyy="0.0010440299884710133" izz="0.0015691435565838765" ixy="-2.5445287803113017e-07" iyz="2.5450084101374172e-05" ixz="1.9763914162541144e-09" />
        </inertial>
        <visual name="Joint_visual">
            <origin xyz="1.050520474551156e-11 -0.10999999836087171 0.009999999999999966" rpy="3.141592653589793 -1.5707963267948963 0" />
            <geometry>
                <mesh filename="package://moveit_bot_rope_bot_description/meshes/Joint.stl" scale="0.001 0.001 0.001" />
            </geometry>
        </visual>
        <collision name="Joint_collision">
            <origin xyz="1.050520474551156e-11 -0.10999999836087171 0.009999999999999966" rpy="3.141592653589793 -1.5707963267948963 0" />
            <geometry>
                <mesh filename="package://moveit_bot_rope_bot_description/meshes/Joint.stl" scale="0.001 0.001 0.001" />
            </geometry>
        </collision>
    </link>
    <link name="Rope_tensioner">
        <inertial>
            <origin xyz="-8.783161725154544e-05 -9.003482913107518e-05 0.005958148218763455" rpy="0.0 -0.0 0.0" />
            <mass value="0.019469218394604033" />
            <inertia ixx="1.2630260627525332e-06" iyy="8.273092067539079e-07" izz="1.9992446528886363e-06" ixy="7.119441108566219e-12" iyz="9.147880233153533e-11" ixz="-2.9388098657904052e-09" />
        </inertial>
        <visual name="Rope_tensioner_visual">
            <origin xyz="-8.881784197001262e-18 -7.171432646509158e-10 -0.13596549836087232" rpy="-1.5707963267948961 1.8522930615155404e-16 6.713660007292138e-17" />
            <geometry>
                <mesh filename="package://moveit_bot_rope_bot_description/meshes/Rope_tensioner.stl" scale="0.001 0.001 0.001" />
            </geometry>
        </visual>
        <collision name="Rope_tensioner_collision">
            <origin xyz="-8.881784197001262e-18 -7.171432646509158e-10 -0.13596549836087232" rpy="-1.5707963267948961 1.8522930615155404e-16 6.713660007292138e-17" />
            <geometry>
                <mesh filename="package://moveit_bot_rope_bot_description/meshes/Rope_tensioner.stl" scale="0.001 0.001 0.001" />
            </geometry>
        </collision>
    </link>
    <link name="cONNECTOR">
        <inertial>
            <origin xyz="-5.2555502308719224e-12 -0.05506576329366768 0.001979143302621327" rpy="0.0 -0.0 0.0" />
            <mass value="0.06391965649415227" />
            <inertia ixx="9.962063520082333e-05" iyy="1.189003953376829e-06" izz="0.00010002310597693483" ixy="9.437422509105186e-15" iyz="2.186774416480428e-09" ixz="9.707113252093717e-20" />
        </inertial>
        <visual name="cONNECTOR_visual">
            <origin xyz="0.0 0.0 -0.01" rpy="-0.0 1.5707963267948966 0" />
            <geometry>
                <mesh filename="package://moveit_bot_rope_bot_description/meshes/cONNECTOR.stl" scale="0.001 0.001 0.001" />
            </geometry>
        </visual>
        <collision name="cONNECTOR_collision">
            <origin xyz="0.0 0.0 -0.01" rpy="-0.0 1.5707963267948966 0" />
            <geometry>
                <mesh filename="package://moveit_bot_rope_bot_description/meshes/cONNECTOR.stl" scale="0.001 0.001 0.001" />
            </geometry>
        </collision>
    </link>
    <link name="Joint1">
        <inertial>
            <origin xyz="-0.02999283603830911 -0.016161140412826853 0.010283924884042919" rpy="3.6625391965037886e-94 -0.0 0.0" />
            <mass value="0.9819884881906905" />
            <inertia ixx="0.0005938487526790121" iyy="0.0010440299884710172" izz="0.0015691435565836666" ixy="-2.544528779897359e-07" iyz="2.5450084101381887e-05" ixz="1.976391417231204e-09" />
        </inertial>
        <visual name="Joint1_visual">
            <origin xyz="-0.02999999998949532 -0.11999999836087184 0.009999999999999894" rpy="3.141592653589793 -1.5707963267948963 0" />
            <geometry>
                <mesh filename="package://moveit_bot_rope_bot_description/meshes/Joint1.stl" scale="0.001 0.001 0.001" />
            </geometry>
        </visual>
        <collision name="Joint1_collision">
            <origin xyz="-0.02999999998949532 -0.11999999836087184 0.009999999999999894" rpy="3.141592653589793 -1.5707963267948963 0" />
            <geometry>
                <mesh filename="package://moveit_bot_rope_bot_description/meshes/Joint1.stl" scale="0.001 0.001 0.001" />
            </geometry>
        </collision>
    </link>
    <link name="Joint_M1">
        <inertial>
            <origin xyz="0.03000714508234241 0.01616115961350538 0.009716075253507529" rpy="0.0 -0.0 0.0" />
            <mass value="0.9819872908083896" />
            <inertia ixx="0.000593846722555947" iyy="0.0010440284532366136" izz="0.00156914009900503" ixy="2.536862635589029e-07" iyz="2.5450173894266942e-05" ixz="-2.043373002773229e-09" />
        </inertial>
        <visual name="Joint_M1_visual">
            <origin xyz="0.029999999999999895 0.00999999999999997 0.01" rpy="-3.141592653589793 -1.5707963267948961 0" />
            <geometry>
                <mesh filename="package://moveit_bot_rope_bot_description/meshes/Joint_M1.stl" scale="0.001 0.001 0.001" />
            </geometry>
        </visual>
        <collision name="Joint_M1_collision">
            <origin xyz="0.029999999999999895 0.00999999999999997 0.01" rpy="-3.141592653589793 -1.5707963267948961 0" />
            <geometry>
                <mesh filename="package://moveit_bot_rope_bot_description/meshes/Joint_M1.stl" scale="0.001 0.001 0.001" />
            </geometry>
        </collision>
    </link>
    <link name="angle_arm">
        <inertial>
            <origin xyz="2.2131878450690763e-11 -0.015812719501657604 0.02150750920030209" rpy="-1.9446922743316076e-62 -0.0 -5.473822126268818e-48" />
            <mass value="0.48225161028570596" />
            <inertia ixx="0.00021589784681706568" iyy="0.0002557365135636336" izz="0.00032530743099385545" ixy="-1.1723698069440752e-13" iyz="7.258610739028624e-05" ixz="7.573673641531908e-14" />
        </inertial>
        <visual name="angle_arm_visual">
            <origin xyz="1.0505118021380721e-11 -0.05499999836087231 0.15500000230968006" rpy="1.5707963267948968 1.5025706269906798e-16 -1.5707963267948968" />
            <geometry>
                <mesh filename="package://moveit_bot_rope_bot_description/meshes/angle_arm.stl" scale="0.001 0.001 0.001" />
            </geometry>
        </visual>
        <collision name="angle_arm_collision">
            <origin xyz="1.0505118021380721e-11 -0.05499999836087231 0.15500000230968006" rpy="1.5707963267948968 1.5025706269906798e-16 -1.5707963267948968" />
            <geometry>
                <mesh filename="package://moveit_bot_rope_bot_description/meshes/angle_arm.stl" scale="0.001 0.001 0.001" />
            </geometry>
        </collision>
    </link>
    <link name="Joint_M2">
        <inertial>
            <origin xyz="7.145092847701479e-06 -0.009716073465368248 0.016161157646305213" rpy="0.0 -0.0 0.0" />
            <mass value="0.9819872908083896" />
            <inertia ixx="0.0005938467225559511" iyy="0.0015691400990050265" izz="0.00104402845323662" ixy="2.043373002436004e-09" iyz="-2.5450173894268555e-05" ixz="2.536862635591037e-07" />
        </inertial>
        <visual name="Joint_M2_visual">
            <origin xyz="1.0505187830744945e-11 -0.00999999821186071 0.009999998032799785" rpy="-1.5707963267948966 1.7437209123740705e-17 -1.5707963267948966" />
            <geometry>
                <mesh filename="package://moveit_bot_rope_bot_description/meshes/Joint_M2.stl" scale="0.001 0.001 0.001" />
            </geometry>
        </visual>
        <collision name="Joint_M2_collision">
            <origin xyz="1.0505187830744945e-11 -0.00999999821186071 0.009999998032799785" rpy="-1.5707963267948966 1.7437209123740705e-17 -1.5707963267948966" />
            <geometry>
                <mesh filename="package://moveit_bot_rope_bot_description/meshes/Joint_M2.stl" scale="0.001 0.001 0.001" />
            </geometry>
        </collision>
    </link>
    <link name="Joint2">
        <inertial>
            <origin xyz="7.163951185597763e-06 0.009716076904096394 -0.0061611423800270165" rpy="0.0 -0.0 0.0" />
            <mass value="0.9819884881906905" />
            <inertia ixx="0.0005938487526790451" iyy="0.0015691435565837047" izz="0.0010440299884710235" ixy="-1.9763914157323e-09" iyz="-2.545008410137148e-05" ixz="-2.544528780424385e-07" />
        </inertial>
        <visual name="Joint2_visual">
            <origin xyz="-1.2385925618474404e-16 0.010000001788139343 -0.1100000003280723" rpy="-1.5707963267948968 5.752564471458263e-17 -1.5707963267948968" />
            <geometry>
                <mesh filename="package://moveit_bot_rope_bot_description/meshes/Joint2.stl" scale="0.001 0.001 0.001" />
            </geometry>
        </visual>
        <collision name="Joint2_collision">
            <origin xyz="-1.2385925618474404e-16 0.010000001788139343 -0.1100000003280723" rpy="-1.5707963267948968 5.752564471458263e-17 -1.5707963267948968" />
            <geometry>
                <mesh filename="package://moveit_bot_rope_bot_description/meshes/Joint2.stl" scale="0.001 0.001 0.001" />
            </geometry>
        </collision>
    </link>
    <link name="Joint_M3">
        <inertial>
            <origin xyz="-0.029992854907152342 -0.009716073465368229 0.01616115764630523" rpy="0.0 -0.0 0.0" />
            <mass value="0.9819872908083896" />
            <inertia ixx="0.0005938467225559546" iyy="0.0015691400990050265" izz="0.0010440284532366195" ixy="2.043373002471209e-09" iyz="-2.5450173894268988e-05" ixz="2.5368626355910076e-07" />
        </inertial>
        <visual name="Joint_M3_visual">
            <origin xyz="-0.029999999989494857 -0.009999998211860692 0.009999998032799811" rpy="-1.5707963267948966 1.743720912374032e-17 -1.5707963267948966" />
            <geometry>
                <mesh filename="package://moveit_bot_rope_bot_description/meshes/Joint_M3.stl" scale="0.001 0.001 0.001" />
            </geometry>
        </visual>
        <collision name="Joint_M3_collision">
            <origin xyz="-0.029999999989494857 -0.009999998211860692 0.009999998032799811" rpy="-1.5707963267948966 1.743720912374032e-17 -1.5707963267948966" />
            <geometry>
                <mesh filename="package://moveit_bot_rope_bot_description/meshes/Joint_M3.stl" scale="0.001 0.001 0.001" />
            </geometry>
        </collision>
    </link>
    <link name="cONNECTOR1">
        <inertial>
            <origin xyz="-5.25571234501115e-12 -0.0019791415144819967 0.054934240655140076" rpy="0.0 -0.0 0.0" />
            <mass value="0.06391965649415227" />
            <inertia ixx="9.962063520082328e-05" iyy="0.00010002310597693478" izz="1.1890039533768562e-06" ixy="-8.02231303150022e-20" iyz="-2.1867744165481907e-09" ixz="9.43742114282213e-15" />
        </inertial>
        <visual name="cONNECTOR1_visual">
            <origin xyz="-1.5987211554602254e-16 0.010000001788139326 0.11000000394880775" rpy="1.5707963267948966 -3.036912863133413e-17 1.5707963267948966" />
            <geometry>
                <mesh filename="package://moveit_bot_rope_bot_description/meshes/cONNECTOR1.stl" scale="0.001 0.001 0.001" />
            </geometry>
        </visual>
        <collision name="cONNECTOR1_collision">
            <origin xyz="-1.5987211554602254e-16 0.010000001788139326 0.11000000394880775" rpy="1.5707963267948966 -3.036912863133413e-17 1.5707963267948966" />
            <geometry>
                <mesh filename="package://moveit_bot_rope_bot_description/meshes/cONNECTOR1.stl" scale="0.001 0.001 0.001" />
            </geometry>
        </collision>
    </link>
    <link name="Joint3">
        <inertial>
            <origin xyz="-0.02999283604881443 -0.00971607690409642 0.016161142380026982" rpy="0.0 -0.0 0.0" />
            <mass value="0.9819884881906905" />
            <inertia ixx="0.0005938487526790312" iyy="0.0015691435565836978" izz="0.0010440299884710265" ixy="1.9763914131311147e-09" iyz="-2.545008410137148e-05" ixz="2.5445287803656325e-07" />
        </inertial>
        <visual name="Joint3_visual">
            <origin xyz="-0.030000000000000183 -0.010000001788139389 0.12000000032807244" rpy="1.5707963267948966 -2.492011083483375e-16 1.5707963267948968" />
            <geometry>
                <mesh filename="package://moveit_bot_rope_bot_description/meshes/Joint3.stl" scale="0.001 0.001 0.001" />
            </geometry>
        </visual>
        <collision name="Joint3_collision">
            <origin xyz="-0.030000000000000183 -0.010000001788139389 0.12000000032807244" rpy="1.5707963267948966 -2.492011083483375e-16 1.5707963267948968" />
            <geometry>
                <mesh filename="package://moveit_bot_rope_bot_description/meshes/Joint3.stl" scale="0.001 0.001 0.001" />
            </geometry>
        </collision>
    </link>
    <link name="Arm_mount">
        <inertial>
            <origin xyz="-0.029999966182487486 0.018711288264646086 -0.029706013983883253" rpy="0.0 -0.0 0.0" />
            <mass value="0.7363463596689926" />
            <inertia ixx="0.0005574993631427896" iyy="0.0004619537765787052" izz="0.0005669227978182343" ixy="-2.6930366779300985e-10" iyz="3.386570942100729e-05" ixz="5.948263686067212e-10" />
        </inertial>
        <visual name="Arm_mount_visual">
            <origin xyz="-0.030000000000000124 0.02999999865889546 0.009999996051192141" rpy="-1.5707963267948966 2.4920110834833775e-16 -1.5707963267948963" />
            <geometry>
                <mesh filename="package://moveit_bot_rope_bot_description/meshes/Arm_mount.stl" scale="0.001 0.001 0.001" />
            </geometry>
        </visual>
        <collision name="Arm_mount_collision">
            <origin xyz="-0.030000000000000124 0.02999999865889546 0.009999996051192141" rpy="-1.5707963267948966 2.4920110834833775e-16 -1.5707963267948963" />
            <geometry>
                <mesh filename="package://moveit_bot_rope_bot_description/meshes/Arm_mount.stl" scale="0.001 0.001 0.001" />
            </geometry>
        </collision>
    </link>
    <link name="CF_rod">
        <inertial>
            <origin xyz="0.07500000461936022 1.3833074950045256e-16 -1.490115906221945e-09" rpy="0.0 -0.0 0.0" />
            <mass value="0.24507367941113115" />
            <inertia ixx="4.3408675465696277e-05" iyy="0.000481217486628719" izz="0.00048121748662871555" ixy="2.2484038732604474e-19" iyz="-1.115552178258405e-20" ixz="-1.734723475976807e-18" />
        </inertial>
        <visual name="CF_rod_visual">
            <origin xyz="-0.05496548962197263 1.2878587085651815e-16 0.00999999865889544" rpy="1.5707963267948968 1.5707963267948946 0" />
            <geometry>
                <mesh filename="package://moveit_bot_rope_bot_description/meshes/CF_rod.stl" scale="0.001 0.001 0.001" />
            </geometry>
        </visual>
        <collision name="CF_rod_collision">
            <origin xyz="-0.05496548962197263 1.2878587085651815e-16 0.00999999865889544" rpy="1.5707963267948968 1.5707963267948946 0" />
            <geometry>
                <mesh filename="package://moveit_bot_rope_bot_description/meshes/CF_rod.stl" scale="0.001 0.001 0.001" />
            </geometry>
        </collision>
    </link>
    <link name="elbow_mount">
        <inertial>
            <origin xyz="-0.04499999538063982 -0.008395681551970275 -1.4901160305669237e-09" rpy="0.0 -0.0 0.0" />
            <mass value="0.5164180627679842" />
            <inertia ixx="0.00016621685366904047" iyy="0.000443496363467466" izz="0.00041988487493837406" ixy="2.168404344971009e-19" iyz="1.3852493433040439e-18" ixz="4.188351369318189e-35" />
        </inertial>
        <visual name="elbow_mount_visual">
            <origin xyz="0.19274724558172537 -0.03221825592107085 -0.010000001639126888" rpy="-3.1415926535897922 -1.5707963267948941 0" />
            <geometry>
                <mesh filename="package://moveit_bot_rope_bot_description/meshes/elbow_mount.stl" scale="0.001 0.001 0.001" />
            </geometry>
        </visual>
        <collision name="elbow_mount_collision">
            <origin xyz="0.19274724558172537 -0.03221825592107085 -0.010000001639126888" rpy="-3.1415926535897922 -1.5707963267948941 0" />
            <geometry>
                <mesh filename="package://moveit_bot_rope_bot_description/meshes/elbow_mount.stl" scale="0.001 0.001 0.001" />
            </geometry>
        </collision>
    </link>
    <link name="Joint_M4">
        <inertial>
            <origin xyz="-7.140462982420104e-06 -0.009716071101199932 -0.016161158614880485" rpy="0.0 -0.0 0.0" />
            <mass value="0.9819872908083896" />
            <inertia ixx="0.0005938467225559537" iyy="0.001569140099005023" izz="0.0010440284532366312" ixy="-2.0433730020530394e-09" iyz="2.545017389426812e-05" ixz="2.536862635620085e-07" />
        </inertial>
        <visual name="Joint_M4_visual">
            <origin xyz="4.619360112201321e-09 -0.009999995847692397 -0.009999999001375066" rpy="1.5707963267948992 -1.4846183028048274e-16 -1.570796326794896" />
            <geometry>
                <mesh filename="package://moveit_bot_rope_bot_description/meshes/Joint_M4.stl" scale="0.001 0.001 0.001" />
            </geometry>
        </visual>
        <collision name="Joint_M4_collision">
            <origin xyz="4.619360112201321e-09 -0.009999995847692397 -0.009999999001375066" rpy="1.5707963267948992 -1.4846183028048274e-16 -1.570796326794896" />
            <geometry>
                <mesh filename="package://moveit_bot_rope_bot_description/meshes/Joint_M4.stl" scale="0.001 0.001 0.001" />
            </geometry>
        </collision>
    </link>
    <link name="Joint_M5">
        <inertial>
            <origin xyz="0.009716071101199866 0.01616115861488045 -0.03000715046298268" rpy="0.0 -0.0 0.0" />
            <mass value="0.9819872908083896" />
            <inertia ixx="0.0015691400990050092" iyy="0.0010440284532366312" izz="0.0005938467225559537" ixy="2.5450173894268555e-05" iyz="-2.5368626355853907e-07" ixz="2.0433729985835924e-09" />
        </inertial>
        <visual name="Joint_M5_visual">
            <origin xyz="0.009999995847692329 0.009999999001375031 -0.030000005380640148" rpy="-3.141592653589791 -7.909721570833463e-16 -1.4846183028048247e-16" />
            <geometry>
                <mesh filename="package://moveit_bot_rope_bot_description/meshes/Joint_M5.stl" scale="0.001 0.001 0.001" />
            </geometry>
        </visual>
        <collision name="Joint_M5_collision">
            <origin xyz="0.009999995847692329 0.009999999001375031 -0.030000005380640148" rpy="-3.141592653589791 -7.909721570833463e-16 -1.4846183028048247e-16" />
            <geometry>
                <mesh filename="package://moveit_bot_rope_bot_description/meshes/Joint_M5.stl" scale="0.001 0.001 0.001" />
            </geometry>
        </collision>
    </link>
    <link name="cONNECTOR2">
        <inertial>
            <origin xyz="0.0019791391503136426 0.055065762295042675 4.63511497628133e-09" rpy="0.0 -0.0 0.0" />
            <mass value="0.06391965649415227" />
            <inertia ixx="0.00010002310597693499" iyy="1.1890039533770866e-06" izz="9.962063520082328e-05" ixy="-2.186774416602401e-09" iyz="-9.437763071051819e-15" ixz="-5.390553710169366e-41" />
        </inertial>
        <visual name="cONNECTOR2_visual">
            <origin xyz="-0.01000000415230768 -9.98624951620286e-10 4.640370434572105e-09" rpy="-1.7350979079948066e-15 7.846005561865407e-16 3.141592653589793" />
            <geometry>
                <mesh filename="package://moveit_bot_rope_bot_description/meshes/cONNECTOR2.stl" scale="0.001 0.001 0.001" />
            </geometry>
        </visual>
        <collision name="cONNECTOR2_collision">
            <origin xyz="-0.01000000415230768 -9.98624951620286e-10 4.640370434572105e-09" rpy="-1.7350979079948066e-15 7.846005561865407e-16 3.141592653589793" />
            <geometry>
                <mesh filename="package://moveit_bot_rope_bot_description/meshes/cONNECTOR2.stl" scale="0.001 0.001 0.001" />
            </geometry>
        </collision>
    </link>
    <link name="Joint4">
        <inertial>
            <origin xyz="-0.009716079268264694 -0.006161141411452 -7.1593213204579344e-06" rpy="-2.6112695571015624e-93 -0.0 0.0" />
            <mass value="0.9819884881906905" />
            <inertia ixx="0.0015691435565836909" iyy="0.0010440299884710152" izz="0.0005938487526790312" ixy="2.545008410137148e-05" iyz="2.544528780457078e-07" ixz="-1.976391411639966e-09" />
        </inertial>
        <visual name="Joint4_visual">
            <origin xyz="-0.010000004152307654 -0.10999999935949747 4.629865060223892e-09" rpy="-3.141592653589791 -7.846005561865408e-16 -1.4846183028048294e-16" />
            <geometry>
                <mesh filename="package://moveit_bot_rope_bot_description/meshes/Joint4.stl" scale="0.001 0.001 0.001" />
            </geometry>
        </visual>
        <collision name="Joint4_collision">
            <origin xyz="-0.010000004152307654 -0.10999999935949747 4.629865060223892e-09" rpy="-3.141592653589791 -7.846005561865408e-16 -1.4846183028048294e-16" />
            <geometry>
                <mesh filename="package://moveit_bot_rope_bot_description/meshes/Joint4.stl" scale="0.001 0.001 0.001" />
            </geometry>
        </collision>
    </link>
    <link name="Joint5">
        <inertial>
            <origin xyz="-0.009716079268264713 0.016161141411451967 0.030007169321320432" rpy="0.0 -0.0 0.0" />
            <mass value="0.9819884881906905" />
            <inertia ixx="0.0015691435565836631" iyy="0.0010440299884710014" izz="0.0005938487526790208" ixy="-2.5450084101372346e-05" iyz="2.544528780457078e-07" ixz="1.9763914133746896e-09" />
        </inertial>
        <visual name="Joint5_visual">
            <origin xyz="-0.010000004152307672 0.11999999935949744 0.030000005370134915" rpy="2.204019392284397e-15 7.8460150909860315e-16 1.4846183028048274e-16" />
            <geometry>
                <mesh filename="package://moveit_bot_rope_bot_description/meshes/Joint5.stl" scale="0.001 0.001 0.001" />
            </geometry>
        </visual>
        <collision name="Joint5_collision">
            <origin xyz="-0.010000004152307672 0.11999999935949744 0.030000005370134915" rpy="2.204019392284397e-15 7.8460150909860315e-16 1.4846183028048274e-16" />
            <geometry>
                <mesh filename="package://moveit_bot_rope_bot_description/meshes/Joint5.stl" scale="0.001 0.001 0.001" />
            </geometry>
        </collision>
    </link>
    <link name="Arm_mount1">
        <inertial>
            <origin xyz="0.01871128590047781 -0.02970601495245834 0.03000003918764719" rpy="0.0 -0.0 0.0" />
            <mass value="0.7363463596689926" />
            <inertia ixx="0.0004619537765787052" iyy="0.0005669227978182395" izz="0.0005574993631427966" ixy="3.386570942100816e-05" iyz="5.948263548383181e-10" ixz="-2.693036679074501e-10" />
        </inertial>
        <visual name="Arm_mount1_visual">
            <origin xyz="0.029999996294727146 0.009999995082617055 0.03000000537013463" rpy="-2.5236958357195377e-15 -7.846015090986033e-16 -3.141592653589793" />
            <geometry>
                <mesh filename="package://moveit_bot_rope_bot_description/meshes/Arm_mount1.stl" scale="0.001 0.001 0.001" />
            </geometry>
        </visual>
        <collision name="Arm_mount1_collision">
            <origin xyz="0.029999996294727146 0.009999995082617055 0.03000000537013463" rpy="-2.5236958357195377e-15 -7.846015090986033e-16 -3.141592653589793" />
            <geometry>
                <mesh filename="package://moveit_bot_rope_bot_description/meshes/Arm_mount1.stl" scale="0.001 0.001 0.001" />
            </geometry>
        </collision>
    </link>
    <link name="CF_rod1">
        <inertial>
            <origin xyz="4.629865557603807e-09 3.8542841185318365e-09 -0.07499999558793519" rpy="0.0 -0.0 0.0" />
            <mass value="0.24507367941113115" />
            <inertia ixx="0.0004812174866287225" iyy="0.0004812174866287225" izz="4.3408675465702456e-05" ixy="-4.336808689942018e-19" iyz="-1.3010426069826053e-18" ixz="6.381864596916067e-51" />
        </inertial>
        <visual name="CF_rod1_visual">
            <origin xyz="0.010000004778877525 3.854283736615116e-09 -0.20496548982926802" rpy="1.5707963267948997 2.5236958357195353e-15 -3.1415926535897927" />
            <geometry>
                <mesh filename="package://moveit_bot_rope_bot_description/meshes/CF_rod1.stl" scale="0.001 0.001 0.001" />
            </geometry>
        </visual>
        <collision name="CF_rod1_collision">
            <origin xyz="0.010000004778877525 3.854283736615116e-09 -0.20496548982926802" rpy="1.5707963267948997 2.5236958357195353e-15 -3.1415926535897927" />
            <geometry>
                <mesh filename="package://moveit_bot_rope_bot_description/meshes/CF_rod1.stl" scale="0.001 0.001 0.001" />
            </geometry>
        </collision>
    </link>
    <link name="elbow_mount1">
        <inertial>
            <origin xyz="4.629865486549534e-09 -0.0083956776976863 0.04500000441206467" rpy="0.0 -0.0 0.0" />
            <mass value="0.5164180627679842" />
            <inertia ixx="0.0004198848749385267" iyy="0.0004434963634674799" izz="0.00016621685366902117" ixy="-1.7347234759768063e-18" iyz="3.503403898367997e-18" ixz="-6.938893903907228e-18" />
        </inertial>
        <visual name="elbow_mount1_visual">
            <origin xyz="-0.009999995519145273 -0.032218252066787544 -0.19274723655030016" rpy="3.1415926535897913 -3.083500311469751e-15 6.009044892265013e-16" />
            <geometry>
                <mesh filename="package://moveit_bot_rope_bot_description/meshes/elbow_mount1.stl" scale="0.001 0.001 0.001" />
            </geometry>
        </visual>
        <collision name="elbow_mount1_collision">
            <origin xyz="-0.009999995519145273 -0.032218252066787544 -0.19274723655030016" rpy="3.1415926535897913 -3.083500311469751e-15 6.009044892265013e-16" />
            <geometry>
                <mesh filename="package://moveit_bot_rope_bot_description/meshes/elbow_mount1.stl" scale="0.001 0.001 0.001" />
            </geometry>
        </collision>
    </link>
    <link name="Joint_M6">
        <inertial>
            <origin xyz="-0.016161152494898978 -0.009716077246915927 7.149494407130419e-06" rpy="0.0 2.2394529668069603e-62 0.0" />
            <mass value="0.9819872908083896" />
            <inertia ixx="0.0010440284532366312" iyy="0.0015691400990050226" izz="0.0005938467225559266" ixy="2.5450173894266816e-05" iyz="2.0433730055224855e-09" ixz="-2.536862635654779e-07" />
        </inertial>
        <visual name="Joint_M6_visual">
            <origin xyz="-0.009999992881393567 -0.01000000199340839 4.412064669168103e-09" rpy="3.022267971512369e-15 -1.8752973789344804e-15 -1.5707963267948961" />
            <geometry>
                <mesh filename="package://moveit_bot_rope_bot_description/meshes/Joint_M6.stl" scale="0.001 0.001 0.001" />
            </geometry>
        </visual>
        <collision name="Joint_M6_collision">
            <origin xyz="-0.009999992881393567 -0.01000000199340839 4.412064669168103e-09" rpy="3.022267971512369e-15 -1.8752973789344804e-15 -1.5707963267948961" />
            <geometry>
                <mesh filename="package://moveit_bot_rope_bot_description/meshes/Joint_M6.stl" scale="0.001 0.001 0.001" />
            </geometry>
        </collision>
    </link>
    <link name="Joint_M7">
        <inertial>
            <origin xyz="0.00971607724691589 -0.03000714949440763 -0.016161152494898908" rpy="0.0 -0.0 0.0" />
            <mass value="0.9819872908083896" />
            <inertia ixx="0.0015691400990050786" iyy="0.0005938467225559407" izz="0.001044028453236645" ixy="2.0433729951141455e-09" iyz="2.536862635516002e-07" ixz="-2.545017389426335e-05" />
        </inertial>
        <visual name="Joint_M7_visual">
            <origin xyz="0.010000001993408354 -0.030000004412065167 -0.009999992881393496" rpy="1.5707963267948997 -6.026406496580937e-16 -1.9977620588492156e-15" />
            <geometry>
                <mesh filename="package://moveit_bot_rope_bot_description/meshes/Joint_M7.stl" scale="0.001 0.001 0.001" />
            </geometry>
        </visual>
        <collision name="Joint_M7_collision">
            <origin xyz="0.010000001993408354 -0.030000004412065167 -0.009999992881393496" rpy="1.5707963267948997 -6.026406496580937e-16 -1.9977620588492156e-15" />
            <geometry>
                <mesh filename="package://moveit_bot_rope_bot_description/meshes/Joint_M7.stl" scale="0.001 0.001 0.001" />
            </geometry>
        </collision>
    </link>
    <link name="cONNECTOR3">
        <inertial>
            <origin xyz="0.0019791452960296672 -4.396310018250915e-09 -0.05506575617506112" rpy="0.0 -0.0 0.0" />
            <mass value="0.06391965649415227" />
            <inertia ixx="0.00010002310597693326" iyy="9.962063520082328e-05" izz="1.1890039533753519e-06" ixy="4.3368086899420173e-19" iyz="9.438630432789807e-15" ixz="2.186774416710821e-09" />
        </inertial>
        <visual name="cONNECTOR3_visual">
            <origin xyz="-0.009999998006591682 -4.391054559960139e-09 7.1186065042638805e-09" rpy="1.5707963267948934 6.026406496580934e-16 3.1415926535897913" />
            <geometry>
                <mesh filename="package://moveit_bot_rope_bot_description/meshes/cONNECTOR3.stl" scale="0.001 0.001 0.001" />
            </geometry>
        </visual>
        <collision name="cONNECTOR3_collision">
            <origin xyz="-0.009999998006591682 -4.391054559960139e-09 7.1186065042638805e-09" rpy="1.5707963267948934 6.026406496580934e-16 3.1415926535897913" />
            <geometry>
                <mesh filename="package://moveit_bot_rope_bot_description/meshes/cONNECTOR3.stl" scale="0.001 0.001 0.001" />
            </geometry>
        </collision>
    </link>
    <link name="Joint6">
        <inertial>
            <origin xyz="-0.009716073122548715 -7.168352745168249e-06 0.006161137531433419" rpy="0.0 -0.0 0.0" />
            <mass value="0.9819884881906905" />
            <inertia ixx="0.0015691435565836631" iyy="0.0005938487526790243" izz="0.0010440299884710291" ixy="-1.976391408170519e-09" iyz="-2.5445287801795224e-07" ixz="-2.5450084101374948e-05" />
        </inertial>
        <visual name="Joint6_visual">
            <origin xyz="-0.009999998006591718 -4.401559721145531e-09 0.1099999954794789" rpy="1.5707963267948999 -6.026406496580928e-16 -1.6338414516989323e-15" />
            <geometry>
                <mesh filename="package://moveit_bot_rope_bot_description/meshes/Joint6.stl" scale="0.001 0.001 0.001" />
            </geometry>
        </visual>
        <collision name="Joint6_collision">
            <origin xyz="-0.009999998006591718 -4.401559721145531e-09 0.1099999954794789" rpy="1.5707963267948999 -6.026406496580928e-16 -1.6338414516989323e-15" />
            <geometry>
                <mesh filename="package://moveit_bot_rope_bot_description/meshes/Joint6.stl" scale="0.001 0.001 0.001" />
            </geometry>
        </collision>
    </link>
    <link name="Joint7">
        <inertial>
            <origin xyz="-0.009716073122548715 -0.029992831647255296 -0.01616114753143343" rpy="-5.613590995862424e-94 -0.0 0.0" />
            <mass value="0.9819884881906905" />
            <inertia ixx="0.0015691435565836631" iyy="0.0005938487526790243" izz="0.0010440299884710014" ixy="1.976391411639966e-09" iyz="-2.5445287803183003e-07" ixz="2.545008410137148e-05" />
        </inertial>
        <visual name="Joint7_visual">
            <origin xyz="-0.009999998006591718 -0.029999995598440743 -0.12000000547947892" rpy="-1.5707963267948934 6.026406496891488e-16 1.6338414516989325e-15" />
            <geometry>
                <mesh filename="package://moveit_bot_rope_bot_description/meshes/Joint7.stl" scale="0.001 0.001 0.001" />
            </geometry>
        </visual>
        <collision name="Joint7_collision">
            <origin xyz="-0.009999998006591718 -0.029999995598440743 -0.12000000547947892" rpy="-1.5707963267948934 6.026406496891488e-16 1.6338414516989325e-15" />
            <geometry>
                <mesh filename="package://moveit_bot_rope_bot_description/meshes/Joint7.stl" scale="0.001 0.001 0.001" />
            </geometry>
        </collision>
    </link>
    <link name="Arm_mount2">
        <inertial>
            <origin xyz="0.01871129204619389 0.030000038219071143 0.029706008832477055" rpy="-5.556593179952604e-94 -0.0 0.0" />
            <mass value="0.7363463596689926" />
            <inertia ixx="0.0004619537765787052" iyy="0.0005574993631427827" izz="0.0005669227978182395" ixy="-2.6930366964217356e-10" iyz="-5.948263756549999e-10" ixz="-3.386570942100729e-05" />
        </inertial>
        <visual name="Arm_mount2_visual">
            <origin xyz="0.030000002440443218 0.030000004401558655 -0.01000000120259834" rpy="1.5707963267948934 -6.026406496891492e-16 -3.141592653589792" />
            <geometry>
                <mesh filename="package://moveit_bot_rope_bot_description/meshes/Arm_mount2.stl" scale="0.001 0.001 0.001" />
            </geometry>
        </visual>
        <collision name="Arm_mount2_collision">
            <origin xyz="0.030000002440443218 0.030000004401558655 -0.01000000120259834" rpy="1.5707963267948934 -6.026406496891492e-16 -3.141592653589792" />
            <geometry>
                <mesh filename="package://moveit_bot_rope_bot_description/meshes/Arm_mount2.stl" scale="0.001 0.001 0.001" />
            </geometry>
        </collision>
    </link>
    <link name="CF_end">
        <inertial>
            <origin xyz="-0.07499999946795395 -2.2914320219058482e-09 4.401558157951513e-09" rpy="0.0 -0.0 0.0" />
            <mass value="0.24507367941113115" />
            <inertia ixx="4.340867546568858e-05" iyy="0.0004812174866287017" izz="0.00048121748662871815" ixy="-8.673617379884035e-19" iyz="-8.673617379884033e-19" ixz="-3.0330004252609884e-35" />
        </inertial>
        <visual name="CF_end_visual">
            <origin xyz="-0.2049654937092868 -2.2914324482314897e-09 0.010000004550569522" rpy="1.5707963267948934 1.5707963267948943 0" />
            <geometry>
                <mesh filename="package://moveit_bot_rope_bot_description/meshes/CF_end.stl" scale="0.001 0.001 0.001" />
            </geometry>
        </visual>
        <collision name="CF_end_collision">
            <origin xyz="-0.2049654937092868 -2.2914324482314897e-09 0.010000004550569522" rpy="1.5707963267948934 1.5707963267948943 0" />
            <geometry>
                <mesh filename="package://moveit_bot_rope_bot_description/meshes/CF_end.stl" scale="0.001 0.001 0.001" />
            </geometry>
        </collision>
    </link>
    <joint name="Joint_M_Rigid-32" type="fixed">
        <origin xyz="0.01 0.01 -0.03" rpy="-3.141592653589793 -1.5707963267948966 0" />
        <parent link="Joint_M" />
        <child link="Joint_M1" />
    </joint>
    <joint name="Joint_M_Revolute-33" type="continuous">
        <origin xyz="-0.01 0.0 0.0" rpy="-0.0 -1.5707963267948966 0" />
        <parent link="Joint_M" />
        <child link="cONNECTOR" />
        <axis xyz="0.0 0.0 1.0" />
    </joint>
    <joint name="cONNECTOR_Revolute-34" type="continuous">
        <origin xyz="0.0 -0.11 0.0" rpy="3.141592653589793 -0.0 0.0" />
        <parent link="cONNECTOR" />
        <child link="Joint" />
        <axis xyz="0.0 0.0 1.0" />
    </joint>
    <joint name="Joint_Rigid-35" type="fixed">
        <origin xyz="0.03 0.01 0.02" rpy="-7.533406174018165e-32 -0.0 2.465190328815662e-32" />
        <parent link="Joint" />
        <child link="Joint1" />
    </joint>
    <joint name="Joint_Rigid-36" type="fixed">
        <origin xyz="-8.586999999999999e-05 0.02496549999999999 0.01" rpy="-1.5707963267948966 -1.5707963267948966 0" />
        <parent link="Joint" />
        <child link="Rope_tensioner" />
    </joint>
    <joint name="Joint1_Rigid-38" type="fixed">
        <origin xyz="-0.03 0.0 0.02" rpy="5.7410063085852e-32 2.4651903288156624e-32 -7.395570986446987e-32" />
        <parent link="Joint1" />
        <child link="angle_arm" />
    </joint>
    <joint name="angle_arm_Rigid-39" type="fixed">
        <origin xyz="-3.549874073494553e-32 -0.044999999999999984 0.035" rpy="1.7975249452528473e-32 -2.4651903288156624e-32 4.930380657631324e-32" />
        <parent link="angle_arm" />
        <child link="Joint_M2" />
    </joint>
    <joint name="Joint_M2_Rigid-44" type="fixed">
        <origin xyz="0.03 -0.02 0.0" rpy="-5.125079819880418e-35 -0.0 0.0" />
        <parent link="Joint_M2" />
        <child link="Joint_M3" />
    </joint>
    <joint name="Joint_M3_Revolute-45" type="continuous">
        <origin xyz="-0.03 -0.02 0.01" rpy="4.717577258900098e-34 3.441101673558767e-84 -1.5407439555097887e-33" />
        <parent link="Joint_M3" />
        <child link="cONNECTOR1" />
        <axis xyz="1.5407439555097887e-33 -1.0 -3.0814879110195774e-33" />
    </joint>
    <joint name="cONNECTOR1_Revolute-46" type="continuous">
        <origin xyz="-2.926826998901563e-51 0.0 0.11" rpy="-1.4134488023184244e-33 7.268578646300764e-67 1.5407439555097887e-33" />
        <parent link="cONNECTOR1" />
        <child link="Joint2" />
        <axis xyz="0.0 1.0 -1.7120630541833097e-33" />
    </joint>
    <joint name="Joint2_Rigid-47" type="fixed">
        <origin xyz="0.03 0.02 0.01" rpy="-3.141592653589793 6.162975822039155e-33 -1.055140320873825e-65" />
        <parent link="Joint2" />
        <child link="Joint3" />
    </joint>
    <joint name="Joint3_Rigid-48" type="fixed">
        <origin xyz="0.0 -0.02 0.0" rpy="-3.9855276505891665e-32 6.162975822039155e-33 -6.162975822039155e-33" />
        <parent link="Joint3" />
        <child link="Arm_mount" />
    </joint>
    <joint name="Arm_mount_Rigid-49" type="fixed">
        <origin xyz="-0.03 0.02 -0.035" rpy="-1.5707963267948966 1.5707963267948966 0" />
        <parent link="Arm_mount" />
        <child link="CF_rod" />
    </joint>
    <joint name="CF_rod_Rigid-50" type="fixed">
        <origin xyz="0.15 0.0 0.0" rpy="-1.2246467991473532e-16 -3.3179134686360395e-32 0.0" />
        <parent link="CF_rod" />
        <child link="elbow_mount" />
    </joint>
    <joint name="elbow_mount_Rigid-51" type="fixed">
        <origin xyz="-0.045 -0.02221826 0.0" rpy="1.2246467991473532e-16 2.189955282635776e-32 -1.1743822828993252e-31" />
        <parent link="elbow_mount" />
        <child link="Joint_M4" />
    </joint>
    <joint name="Joint_M4_Rigid-52" type="fixed">
        <origin xyz="0.030000009999999976 -0.02 0.0" rpy="-1.5707963267948966 -2.7700731456797213e-31 -1.5707963267948966" />
        <parent link="Joint_M4" />
        <child link="Joint_M5" />
    </joint>
    <joint name="Joint_M5_Revolute-58" type="continuous">
        <origin xyz="0.02 0.01 -0.030000009999999976" rpy="0.0 -0.0 0.0" />
        <parent link="Joint_M5" />
        <child link="cONNECTOR2" />
        <axis xyz="1.0 1.2840611789938526e-31 0.0" />
    </joint>
    <joint name="cONNECTOR2_Revolute-59" type="continuous">
        <origin xyz="0.0 0.11 0.0" rpy="-4.930380657631324e-32 -0.0 5.514331908058009e-31" />
        <parent link="cONNECTOR2" />
        <child link="Joint4" />
        <axis xyz="-1.0 -1.9299506106625384e-31 -0.0" />
    </joint>
    <joint name="Joint4_Rigid-60" type="fixed">
        <origin xyz="-0.02 0.01 0.030000009999999976" rpy="-3.141592653589793 -9.860761315262648e-32 -2.0401181010023984e-31" />
        <parent link="Joint4" />
        <child link="Joint5" />
    </joint>
    <joint name="Joint5_Rigid-61" type="fixed">
        <origin xyz="-0.02 0.0 0.0" rpy="-6.039712954913857e-64 -0.0 -1.0947644252537633e-47" />
        <parent link="Joint5" />
        <child link="Arm_mount1" />
    </joint>
    <joint name="Arm_mount1_Rigid-62" type="fixed">
        <origin xyz="0.02 -0.03500001000000001 0.030000009999999976" rpy="-1.5707963267948966 1.5707963267948966 0" />
        <parent link="Arm_mount1" />
        <child link="CF_rod1" />
    </joint>
    <joint name="CF_rod1_Rigid-63" type="fixed">
        <origin xyz="0.0 0.0 -0.14999999999999997" rpy="-1.224646799147352e-16 -8.253995318490843e-32 1.2146231081936874e-63" />
        <parent link="CF_rod1" />
        <child link="elbow_mount1" />
    </joint>
    <joint name="elbow_mount1_Rigid-64" type="fixed">
        <origin xyz="0.0 -0.02221825000000001 0.045" rpy="1.2246467991473572e-16 -1.6067659967718055e-32 5.677687795111464e-32" />
        <parent link="elbow_mount1" />
        <child link="Joint_M6" />
    </joint>
    <joint name="Joint_M6_Rigid-65" type="fixed">
        <origin xyz="0.0 -0.019999999999999983 -0.03" rpy="-1.5707963267948966 -3.412411190289489e-31 -1.5707963267948966" />
        <parent link="Joint_M6" />
        <child link="Joint_M7" />
    </joint>
    <joint name="Joint_M7_Revolute-66" type="continuous">
        <origin xyz="0.02 -0.03 -0.01" rpy="0.0 3.944304526105059e-31 -4.6818346389459024e-31" />
        <parent link="Joint_M7" />
        <child link="cONNECTOR3" />
        <axis xyz="1.0 -4.8366278085538216e-32 0.0" />
    </joint>
    <joint name="cONNECTOR3_Revolute-67" type="continuous">
        <origin xyz="0.0 0.0 -0.10999998999999999" rpy="6.151379695457664e-62 -3.944304526105059e-31 3.116850266431924e-31" />
        <parent link="cONNECTOR3" />
        <child link="Joint6" />
        <axis xyz="-1.0 -1.075897251780348e-31 -0.0" />
    </joint>
    <joint name="Joint6_Rigid-68" type="fixed">
        <origin xyz="-0.02 -0.029999999999999964 -0.01000001000000001" rpy="3.141592653589793 -0.0 1.1497537869624822e-31" />
        <parent link="Joint6" />
        <child link="Joint7" />
    </joint>
    <joint name="Joint7_Rigid-69" type="fixed">
        <origin xyz="-0.01999999999999999 -0.05999999999999996 0.0" rpy="-5.556532427355138e-94 1.2577770170595086e-68 -1.2755374325030065e-37" />
        <parent link="Joint7" />
        <child link="Arm_mount2" />
    </joint>
    <joint name="Arm_mount2_Rigid-70" type="fixed">
        <origin xyz="0.01999999999999999 0.03 0.035" rpy="-1.5707963267948966 1.5707963267948966 0" />
        <parent link="Arm_mount2" />
        <child link="CF_end" />
    </joint>
</robot>