<?xml version='1.0' encoding='utf-8'?>
<robot name="new_urdf_assembly">
    <link name="shoulder">
        <inertial>
            <origin xyz="-7.853433140069155e-08 -0.10641379216315391 -0.0076335389692646465" rpy="0.0 0.0 0.0" />
            <mass value="1.00209496973953" />
            <inertia ixx="0.0008813765274265917" iyy="0.00041153382449582427" izz="0.0009583856240936404" ixy="2.9846514576729824e-09" iyz="-5.003593754259329e-05" ixz="1.0002397421138782e-09" />
        </inertial>
        <visual name="shoulder_visual">
            <origin xyz="0.0 0.0 0.0" rpy="0.0 0.0 0.0" />
            <geometry>
                <mesh filename="package://moveit_bot_bias_bot_description/meshes/shoulder.stl" scale="0.001 0.001 0.001" />
            </geometry>
        </visual>
        <collision name="shoulder_collision">
            <origin xyz="0.0 0.0 0.0" rpy="0.0 0.0 0.0" />
            <geometry>
                <mesh filename="package://moveit_bot_bias_bot_description/meshes/shoulder.stl" scale="0.001 0.001 0.001" />
            </geometry>
        </collision>
    </link>
    <link name="joint">
        <inertial>
            <origin xyz="1.0118791249347226e-10 -0.008594906122159891 0.0024999999999999866" rpy="0.0 -0.0 0.0" />
            <mass value="0.031171001796121915" />
            <inertia ixx="4.146876112089327e-06" iyy="1.1273781104004941e-06" izz="5.1443750483393396e-06" ixy="9.373734156502972e-15" iyz="-1.0164395367051604e-19" ixz="1.0164395367051604e-20" />
        </inertial>
        <visual name="joint_visual">
            <origin xyz="0.005000000149011621 -0.06899999999999987 0.02899999999999994" rpy="3.141592653589793 1.5707963267948961 0" />
            <geometry>
                <mesh filename="package://moveit_bot_bias_bot_description/meshes/joint.stl" scale="0.001 0.001 0.001" />
            </geometry>
        </visual>
        <collision name="joint_collision">
            <origin xyz="0.005000000149011621 -0.06899999999999987 0.02899999999999994" rpy="3.141592653589793 1.5707963267948961 0" />
            <geometry>
                <mesh filename="package://moveit_bot_bias_bot_description/meshes/joint.stl" scale="0.001 0.001 0.001" />
            </geometry>
        </collision>
    </link>
    <link name="arm">
        <inertial>
            <origin xyz="0.0026585919301290997 -0.01918221579033086 -0.024000571816830726" rpy="0.0 -0.0 0.0" />
            <mass value="0.5711036137259029" />
            <inertia ixx="0.00020878598785673046" iyy="0.00015346622537076968" izz="0.00023149872173090373" ixy="9.115549979373943e-06" iyz="-1.8928363147603315e-09" ixz="-5.6468142581902705e-09" />
        </inertial>
        <visual name="arm_visual">
            <origin xyz="-0.0049999998509883525 -0.04499999999999992 -0.024000000000000066" rpy="-3.141592653589793 -1.5707963267948966 0" />
            <geometry>
                <mesh filename="package://moveit_bot_bias_bot_description/meshes/arm.stl" scale="0.001 0.001 0.001" />
            </geometry>
        </visual>
        <collision name="arm_collision">
            <origin xyz="-0.0049999998509883525 -0.04499999999999992 -0.024000000000000066" rpy="-3.141592653589793 -1.5707963267948966 0" />
            <geometry>
                <mesh filename="package://moveit_bot_bias_bot_description/meshes/arm.stl" scale="0.001 0.001 0.001" />
            </geometry>
        </collision>
    </link>
    <joint name="shoulder_Revolute-1" type="continuous">
        <origin xyz="0.024 -0.069 0.005" rpy="-3.141592653589793 -1.5707963267948966 0" />
        <parent link="shoulder" />
        <child link="joint" />
        <axis xyz="0.0 0.0 1.0" />
    </joint>
    <joint name="joint_Revolute-3" type="continuous">
        <origin xyz="0.0 -0.024000000000000004 0.0" rpy="0.0 -0.0 0.0" />
        <parent link="joint" />
        <child link="arm" />
        <axis xyz="-0.0 0.0 -1.0" />
        <mimic joint="shoulder_Revolute-1" multiplier="-1.0" offset="0.0" />
    </joint>
</robot>